05-Apr-22 23:46:14 - spotipy.client - ERROR - HTTP Error for PUT to https://api.spotify.com/v1/me/player with Params: {} returned 404 due to Device not found
05-Apr-22 23:46:16 - root - ERROR - http status: 404, code:-1 - https://api.spotify.com/v1/me/player:
 Device not found, reason: None
Traceback (most recent call last):
  File "/usr/local/lib/python3.9/dist-packages/spotipy/client.py", line 245, in _internal_call
    response.raise_for_status()
  File "/usr/lib/python3/dist-packages/requests/models.py", line 943, in raise_for_status
    raise HTTPError(http_error_msg, response=self)
requests.exceptions.HTTPError: 404 Client Error: Not Found for url: https://api.spotify.com/v1/me/player

During handling of the above exception, another exception occurred:

Traceback (most recent call last):
  File "/home/pi/Desktop/rfidSpotify/spotify_player.py", line 208, in <module>
    sp.transfer_playback(device_id=DEVICE_ID, force_play=False)
  File "/usr/local/lib/python3.9/dist-packages/spotipy/client.py", line 1726, in transfer_playback
    return self._put("me/player", payload=data)
  File "/usr/local/lib/python3.9/dist-packages/spotipy/client.py", line 312, in _put
    return self._internal_call("PUT", url, payload, kwargs)
  File "/usr/local/lib/python3.9/dist-packages/spotipy/client.py", line 267, in _internal_call
    raise SpotifyException(
spotipy.exceptions.SpotifyException: http status: 404, code:-1 - https://api.spotify.com/v1/me/player:
 Device not found, reason: None
05-Apr-22 23:46:18 - root - ERROR - Cleaning  up...
05-Apr-22 23:46:20 - spotipy.client - ERROR - HTTP Error for PUT to https://api.spotify.com/v1/me/player with Params: {} returned 404 due to Device not found
05-Apr-22 23:46:21 - root - ERROR - http status: 404, code:-1 - https://api.spotify.com/v1/me/player:
 Device not found, reason: None
Traceback (most recent call last):
  File "/usr/local/lib/python3.9/dist-packages/spotipy/client.py", line 245, in _internal_call
    response.raise_for_status()
  File "/usr/lib/python3/dist-packages/requests/models.py", line 943, in raise_for_status
    raise HTTPError(http_error_msg, response=self)
requests.exceptions.HTTPError: 404 Client Error: Not Found for url: https://api.spotify.com/v1/me/player

During handling of the above exception, another exception occurred:

Traceback (most recent call last):
  File "/home/pi/Desktop/rfidSpotify/spotify_player.py", line 208, in <module>
    sp.transfer_playback(device_id=DEVICE_ID, force_play=False)
  File "/usr/local/lib/python3.9/dist-packages/spotipy/client.py", line 1726, in transfer_playback
    return self._put("me/player", payload=data)
  File "/usr/local/lib/python3.9/dist-packages/spotipy/client.py", line 312, in _put
    return self._internal_call("PUT", url, payload, kwargs)
  File "/usr/local/lib/python3.9/dist-packages/spotipy/client.py", line 267, in _internal_call
    raise SpotifyException(
spotipy.exceptions.SpotifyException: http status: 404, code:-1 - https://api.spotify.com/v1/me/player:
 Device not found, reason: None
05-Apr-22 23:46:23 - root - ERROR - Cleaning  up...
05-Apr-22 23:46:25 - spotipy.client - ERROR - HTTP Error for PUT to https://api.spotify.com/v1/me/player with Params: {} returned 404 due to Device not found
05-Apr-22 23:46:26 - root - ERROR - http status: 404, code:-1 - https://api.spotify.com/v1/me/player:
 Device not found, reason: None
Traceback (most recent call last):
  File "/usr/local/lib/python3.9/dist-packages/spotipy/client.py", line 245, in _internal_call
    response.raise_for_status()
  File "/usr/lib/python3/dist-packages/requests/models.py", line 943, in raise_for_status
    raise HTTPError(http_error_msg, response=self)
requests.exceptions.HTTPError: 404 Client Error: Not Found for url: https://api.spotify.com/v1/me/player

During handling of the above exception, another exception occurred:

Traceback (most recent call last):
  File "/home/pi/Desktop/rfidSpotify/spotify_player.py", line 208, in <module>
    sp.transfer_playback(device_id=DEVICE_ID, force_play=False)
  File "/usr/local/lib/python3.9/dist-packages/spotipy/client.py", line 1726, in transfer_playback
    return self._put("me/player", payload=data)
  File "/usr/local/lib/python3.9/dist-packages/spotipy/client.py", line 312, in _put
    return self._internal_call("PUT", url, payload, kwargs)
  File "/usr/local/lib/python3.9/dist-packages/spotipy/client.py", line 267, in _internal_call
    raise SpotifyException(
spotipy.exceptions.SpotifyException: http status: 404, code:-1 - https://api.spotify.com/v1/me/player:
 Device not found, reason: None
05-Apr-22 23:46:28 - root - ERROR - Cleaning  up...
05-Apr-22 23:46:30 - spotipy.client - ERROR - HTTP Error for PUT to https://api.spotify.com/v1/me/player with Params: {} returned 404 due to Device not found
05-Apr-22 23:46:31 - root - ERROR - http status: 404, code:-1 - https://api.spotify.com/v1/me/player:
 Device not found, reason: None
Traceback (most recent call last):
  File "/usr/local/lib/python3.9/dist-packages/spotipy/client.py", line 245, in _internal_call
    response.raise_for_status()
  File "/usr/lib/python3/dist-packages/requests/models.py", line 943, in raise_for_status
    raise HTTPError(http_error_msg, response=self)
requests.exceptions.HTTPError: 404 Client Error: Not Found for url: https://api.spotify.com/v1/me/player

During handling of the above exception, another exception occurred:

Traceback (most recent call last):
  File "/home/pi/Desktop/rfidSpotify/spotify_player.py", line 208, in <module>
    sp.transfer_playback(device_id=DEVICE_ID, force_play=False)
  File "/usr/local/lib/python3.9/dist-packages/spotipy/client.py", line 1726, in transfer_playback
    return self._put("me/player", payload=data)
  File "/usr/local/lib/python3.9/dist-packages/spotipy/client.py", line 312, in _put
    return self._internal_call("PUT", url, payload, kwargs)
  File "/usr/local/lib/python3.9/dist-packages/spotipy/client.py", line 267, in _internal_call
    raise SpotifyException(
spotipy.exceptions.SpotifyException: http status: 404, code:-1 - https://api.spotify.com/v1/me/player:
 Device not found, reason: None
05-Apr-22 23:46:33 - root - ERROR - Cleaning  up...
05-Apr-22 23:46:36 - spotipy.client - ERROR - HTTP Error for PUT to https://api.spotify.com/v1/me/player with Params: {} returned 404 due to Device not found
05-Apr-22 23:46:37 - root - ERROR - http status: 404, code:-1 - https://api.spotify.com/v1/me/player:
 Device not found, reason: None
Traceback (most recent call last):
  File "/usr/local/lib/python3.9/dist-packages/spotipy/client.py", line 245, in _internal_call
    response.raise_for_status()
  File "/usr/lib/python3/dist-packages/requests/models.py", line 943, in raise_for_status
    raise HTTPError(http_error_msg, response=self)
requests.exceptions.HTTPError: 404 Client Error: Not Found for url: https://api.spotify.com/v1/me/player

During handling of the above exception, another exception occurred:

Traceback (most recent call last):
  File "/home/pi/Desktop/rfidSpotify/spotify_player.py", line 208, in <module>
    sp.transfer_playback(device_id=DEVICE_ID, force_play=False)
  File "/usr/local/lib/python3.9/dist-packages/spotipy/client.py", line 1726, in transfer_playback
    return self._put("me/player", payload=data)
  File "/usr/local/lib/python3.9/dist-packages/spotipy/client.py", line 312, in _put
    return self._internal_call("PUT", url, payload, kwargs)
  File "/usr/local/lib/python3.9/dist-packages/spotipy/client.py", line 267, in _internal_call
    raise SpotifyException(
spotipy.exceptions.SpotifyException: http status: 404, code:-1 - https://api.spotify.com/v1/me/player:
 Device not found, reason: None
05-Apr-22 23:46:39 - root - ERROR - Cleaning  up...
05-Apr-22 23:46:41 - spotipy.client - ERROR - HTTP Error for PUT to https://api.spotify.com/v1/me/player with Params: {} returned 404 due to Device not found
05-Apr-22 23:46:42 - root - ERROR - http status: 404, code:-1 - https://api.spotify.com/v1/me/player:
 Device not found, reason: None
Traceback (most recent call last):
  File "/usr/local/lib/python3.9/dist-packages/spotipy/client.py", line 245, in _internal_call
    response.raise_for_status()
  File "/usr/lib/python3/dist-packages/requests/models.py", line 943, in raise_for_status
    raise HTTPError(http_error_msg, response=self)
requests.exceptions.HTTPError: 404 Client Error: Not Found for url: https://api.spotify.com/v1/me/player

During handling of the above exception, another exception occurred:

Traceback (most recent call last):
  File "/home/pi/Desktop/rfidSpotify/spotify_player.py", line 208, in <module>
    sp.transfer_playback(device_id=DEVICE_ID, force_play=False)
  File "/usr/local/lib/python3.9/dist-packages/spotipy/client.py", line 1726, in transfer_playback
    return self._put("me/player", payload=data)
  File "/usr/local/lib/python3.9/dist-packages/spotipy/client.py", line 312, in _put
    return self._internal_call("PUT", url, payload, kwargs)
  File "/usr/local/lib/python3.9/dist-packages/spotipy/client.py", line 267, in _internal_call
    raise SpotifyException(
spotipy.exceptions.SpotifyException: http status: 404, code:-1 - https://api.spotify.com/v1/me/player:
 Device not found, reason: None
05-Apr-22 23:46:43 - root - ERROR - Cleaning  up...
